Workbook

Sheet Бюджет
A1: 💰 БЮДЖЕТ: ДОХОДЫ И РАСХОДЫ
B3: Месяц: | C3: Январь | D3: Год: | F3: 2026
B5: ДОХОД (месяц) | F5: РАСХОД (месяц) | J5: БАЛАНС (месяц)
B6: =SUMPRODUCT(('Журнал операций'!$D$25:$D$224="Доход")*(YEAR('Журнал операций'!$B$25:$B$224+0)=$F$3)*(MONTH('Журнал операций'!$B$25:$B$224+0)=MATCH($C$3,Справочник!$L$3:$L$14,0))*(COUNTIF(Справочник!$C$3:$C$10,'Журнал операций'!$E$25:$E$224)=0)*'Журнал операций'!$F$25:$F$224) | F6: =SUMPRODUCT(('Журнал операций'!$D$25:$D$224="Расход")*(YEAR('Журнал операций'!$B$25:$B$224+0)=$F$3)*(MONTH('Журнал операций'!$B$25:$B$224+0)=MATCH($C$3,Справочник!$L$3:$L$14,0))*(COUNTIF(Справочник!$C$3:$C$10,'Журнал операций'!$E$25:$E$224)=0)*'Журнал операций'!$F$25:$F$224) | J6: =B6-F6
B10: ДОХОДЫ ПО КАТЕГОРИЯМ (месяц) | F10: РАСХОДЫ ПО КАТЕГОРИЯМ (месяц) | J10: ДИНАМИКА ЗА ГОД
B11: Категория | C11: Сумма | D11: % | F11: Категория | G11: Сумма | H11: % | J11: Месяц | K11: Доход | L11: Расход
B12: Зарплата | C12: =SUMPRODUCT(('Журнал операций'!$D$25:$D$224="Доход")*('Журнал операций'!$E$25:$E$224="Зарплата")*(YEAR('Журнал операций'!$B$25:$B$224+0)=$F$3)*(MONTH('Журнал операций'!$B$25:$B$224+0)=MATCH($C$3,Справочник!$L$3:$L$14,0))*'Журнал операций'!$F$25:$F$224) | D12: =IFERROR(C12/$B$6,0) | F12: Аренда | G12: =SUMPRODUCT(('Журнал операций'!$D$25:$D$224="Расход")*('Журнал операций'!$E$25:$E$224="Аренда")*(YEAR('Журнал операций'!$B$25:$B$224+0)=$F$3)*(MONTH('Журнал операций'!$B$25:$B$224+0)=MATCH($C$3,Справочник!$L$3:$L$14,0))*'Журнал операций'!$F$25:$F$224) | H12: =IFERROR(G12/$F$6,0) | J12: =TEXT(DATE($F$3,1,1),"mmm yy") | K12: =SUMPRODUCT(('Журнал операций'!$D$25:$D$224="Доход")*(YEAR('Журнал операций'!$B$25:$B$224+0)=$F$3)*(MONTH('Журнал операций'!$B$25:$B$224+0)=1)*(COUNTIF(Справочник!$C$3:$C$10,'Журнал операций'!$E$25:$E$224)=0)*'Журнал операций'!$F$25:$F$224) | L12: =SUMPRODUCT(('Журнал операций'!$D$25:$D$224="Расход")*(YEAR('Журнал операций'!$B$25:$B$224+0)=$F$3)*(MONTH('Журнал операций'!$B$25:$B$224+0)=1)*(COUNTIF(Справочник!$C$3:$C$10,'Журнал операций'!$E$25:$E$224)=0)*'Журнал операций'!$F$25:$F$224)
B13: Заказы | C13: =SUMPRODUCT(('Журнал операций'!$D$25:$D$224="Доход")*('Журнал операций'!$E$25:$E$224="Заказы")*(YEAR('Журнал операций'!$B$25:$B$224+0)=$F$3)*(MONTH('Журнал операций'!$B$25:$B$224+0)=MATCH($C$3,Справочник!$L$3:$L$14,0))*'Журнал операций'!$F$25:$F$224) | D13: =IFERROR(C13/$B$6,0) | F13: Продукты | G13: =SUMPRODUCT(('Журнал операций'!$D$25:$D$224="Расход")*('Журнал операций'!$E$25:$E$224="Продукты")*(YEAR('Журнал операций'!$B$25:$B$224+0)=$F$3)*(MONTH('Журнал операций'!$B$25:$B$224+0)=MATCH($C$3,Справочник!$L$3:$L$14,0))*'Журнал операций'!$F$25:$F$224) | H13: =IFERROR(G13/$F$6,0) | J13: =TEXT(DATE($F$3,2,1),"mmm yy") | K13: =SUMPRODUCT(('Журнал операций'!$D$25:$D$224="Доход")*(YEAR('Журнал операций'!$B$25:$B$224+0)=$F$3)*(MONTH('Журнал операций'!$B$25:$B$224+0)=2)*(COUNTIF(Справочник!$C$3:$C$10,'Журнал операций'!$E$25:$E$224)=0)*'Журнал операций'!$F$25:$F$224) | L13: =SUMPRODUCT(('Журнал операций'!$D$25:$D$224="Расход")*(YEAR('Журнал операций'!$B$25:$B$224+0)=$F$3)*(MONTH('Журнал операций'!$B$25:$B$224+0)=2)*(COUNTIF(Справочник!$C$3:$C$10,'Журнал операций'!$E$25:$E$224)=0)*'Журнал операций'!$F$25:$F$224)
B14: Подарок | C14: =SUMPRODUCT(('Журнал операций'!$D$25:$D$224="Доход")*('Журнал операций'!$E$25:$E$224="Подарок")*(YEAR('Журнал операций'!$B$25:$B$224+0)=$F$3)*(MONTH('Журнал операций'!$B$25:$B$224+0)=MATCH($C$3,Справочник!$L$3:$L$14,0))*'Журнал операций'!$F$25:$F$224) | D14: =IFERROR(C14/$B$6,0) | F14: Обучение | G14: =SUMPRODUCT(('Журнал операций'!$D$25:$D$224="Расход")*('Журнал операций'!$E$25:$E$224="Обучение")*(YEAR('Журнал операций'!$B$25:$B$224+0)=$F$3)*(MONTH('Журнал операций'!$B$25:$B$224+0)=MATCH($C$3,Справочник!$L$3:$L$14,0))*'Журнал операций'!$F$25:$F$224) | H14: =IFERROR(G14/$F$6,0) | J14: =TEXT(DATE($F$3,3,1),"mmm yy") | K14: =SUMPRODUCT(('Журнал операций'!$D$25:$D$224="Доход")*(YEAR('Журнал операций'!$B$25:$B$224+0)=$F$3)*(MONTH('Журнал операций'!$B$25:$B$224+0)=3)*(COUNTIF(Справочник!$C$3:$C$10,'Журнал операций'!$E$25:$E$224)=0)*'Журнал операций'!$F$25:$F$224) | L14: =SUMPRODUCT(('Журнал операций'!$D$25:$D$224="Расход")*(YEAR('Журнал операций'!$B$25:$B$224+0)=$F$3)*(MONTH('Журнал операций'!$B$25:$B$224+0)=3)*(COUNTIF(Справочник!$C$3:$C$10,'Журнал операций'!$E$25:$E$224)=0)*'Журнал операций'!$F$25:$F$224)
F15: Кредит | G15: =SUMPRODUCT(('Журнал операций'!$D$25:$D$224="Расход")*('Журнал операций'!$E$25:$E$224="Кредит")*(YEAR('Журнал операций'!$B$25:$B$224+0)=$F$3)*(MONTH('Журнал операций'!$B$25:$B$224+0)=MATCH($C$3,Справочник!$L$3:$L$14,0))*'Журнал операций'!$F$25:$F$224) | H15: =IFERROR(G15/$F$6,0) | J15: =TEXT(DATE($F$3,4,1),"mmm yy") | K15: =SUMPRODUCT(('Журнал операций'!$D$25:$D$224="Доход")*(YEAR('Журнал операций'!$B$25:$B$224+0)=$F$3)*(MONTH('Журнал операций'!$B$25:$B$224+0)=4)*(COUNTIF(Справочник!$C$3:$C$10,'Журнал операций'!$E$25:$E$224)=0)*'Журнал операций'!$F$25:$F$224) | L15: =SUMPRODUCT(('Журнал операций'!$D$25:$D$224="Расход")*(YEAR('Журнал операций'!$B$25:$B$224+0)=$F$3)*(MONTH('Журнал операций'!$B$25:$B$224+0)=4)*(COUNTIF(Справочник!$C$3:$C$10,'Журнал операций'!$E$25:$E$224)=0)*'Журнал операций'!$F$25:$F$224)
F16: Субподряд | G16: =SUMPRODUCT(('Журнал операций'!$D$25:$D$224="Расход")*('Журнал операций'!$E$25:$E$224="Субподряд")*(YEAR('Журнал операций'!$B$25:$B$224+0)=$F$3)*(MONTH('Журнал операций'!$B$25:$B$224+0)=MATCH($C$3,Справочник!$L$3:$L$14,0))*'Журнал операций'!$F$25:$F$224) | H16: =IFERROR(G16/$F$6,0) | J16: =TEXT(DATE($F$3,5,1),"mmm yy") | K16: =SUMPRODUCT(('Журнал операций'!$D$25:$D$224="Доход")*(YEAR('Журнал операций'!$B$25:$B$224+0)=$F$3)*(MONTH('Журнал операций'!$B$25:$B$224+0)=5)*(COUNTIF(Справочник!$C$3:$C$10,'Журнал операций'!$E$25:$E$224)=0)*'Журнал операций'!$F$25:$F$224) | L16: =SUMPRODUCT(('Журнал операций'!$D$25:$D$224="Расход")*(YEAR('Журнал операций'!$B$25:$B$224+0)=$F$3)*(MONTH('Журнал операций'!$B$25:$B$224+0)=5)*(COUNTIF(Справочник!$C$3:$C$10,'Журнал операций'!$E$25:$E$224)=0)*'Журнал операций'!$F$25:$F$224)
F17: Ипотека | G17: =SUMPRODUCT(('Журнал операций'!$D$25:$D$224="Расход")*('Журнал операций'!$E$25:$E$224="Ипотека")*(YEAR('Журнал операций'!$B$25:$B$224+0)=$F$3)*(MONTH('Журнал операций'!$B$25:$B$224+0)=MATCH($C$3,Справочник!$L$3:$L$14,0))*'Журнал операций'!$F$25:$F$224) | H17: =IFERROR(G17/$F$6,0) | J17: =TEXT(DATE($F$3,6,1),"mmm yy") | K17: =SUMPRODUCT(('Журнал операций'!$D$25:$D$224="Доход")*(YEAR('Журнал операций'!$B$25:$B$224+0)=$F$3)*(MONTH('Журнал операций'!$B$25:$B$224+0)=6)*(COUNTIF(Справочник!$C$3:$C$10,'Журнал операций'!$E$25:$E$224)=0)*'Журнал операций'!$F$25:$F$224) | L17: =SUMPRODUCT(('Журнал операций'!$D$25:$D$224="Расход")*(YEAR('Журнал операций'!$B$25:$B$224+0)=$F$3)*(MONTH('Журнал операций'!$B$25:$B$224+0)=6)*(COUNTIF(Справочник!$C$3:$C$10,'Журнал операций'!$E$25:$E$224)=0)*'Журнал операций'!$F$25:$F$224)
F18: Подарок | G18: =SUMPRODUCT(('Журнал операций'!$D$25:$D$224="Расход")*('Журнал операций'!$E$25:$E$224="Подарок")*(YEAR('Журнал операций'!$B$25:$B$224+0)=$F$3)*(MONTH('Журнал операций'!$B$25:$B$224+0)=MATCH($C$3,Справочник!$L$3:$L$14,0))*'Журнал операций'!$F$25:$F$224) | H18: =IFERROR(G18/$F$6,0) | J18: =TEXT(DATE($F$3,7,1),"mmm yy") | K18: =SUMPRODUCT(('Журнал операций'!$D$25:$D$224="Доход")*(YEAR('Журнал операций'!$B$25:$B$224+0)=$F$3)*(MONTH('Журнал операций'!$B$25:$B$224+0)=7)*(COUNTIF(Справочник!$C$3:$C$10,'Журнал операций'!$E$25:$E$224)=0)*'Журнал операций'!$F$25:$F$224) | L18: =SUMPRODUCT(('Журнал операций'!$D$25:$D$224="Расход")*(YEAR('Журнал операций'!$B$25:$B$224+0)=$F$3)*(MONTH('Журнал операций'!$B$25:$B$224+0)=7)*(COUNTIF(Справочник!$C$3:$C$10,'Журнал операций'!$E$25:$E$224)=0)*'Журнал операций'!$F$25:$F$224)
F19: Аутсорс | G19: =SUMPRODUCT(('Журнал операций'!$D$25:$D$224="Расход")*('Журнал операций'!$E$25:$E$224="Аутсорс")*(YEAR('Журнал операций'!$B$25:$B$224+0)=$F$3)*(MONTH('Журнал операций'!$B$25:$B$224+0)=MATCH($C$3,Справочник!$L$3:$L$14,0))*'Журнал операций'!$F$25:$F$224) | H19: =IFERROR(G19/$F$6,0) | J19: =TEXT(DATE($F$3,8,1),"mmm yy") | K19: =SUMPRODUCT(('Журнал операций'!$D$25:$D$224="Доход")*(YEAR('Журнал операций'!$B$25:$B$224+0)=$F$3)*(MONTH('Журнал операций'!$B$25:$B$224+0)=8)*(COUNTIF(Справочник!$C$3:$C$10,'Журнал операций'!$E$25:$E$224)=0)*'Журнал операций'!$F$25:$F$224) | L19: =SUMPRODUCT(('Журнал операций'!$D$25:$D$224="Расход")*(YEAR('Журнал операций'!$B$25:$B$224+0)=$F$3)*(MONTH('Журнал операций'!$B$25:$B$224+0)=8)*(COUNTIF(Справочник!$C$3:$C$10,'Журнал операций'!$E$25:$E$224)=0)*'Журнал операций'!$F$25:$F$224)
J20: =TEXT(DATE($F$3,9,1),"mmm yy") | K20: =SUMPRODUCT(('Журнал операций'!$D$25:$D$224="Доход")*(YEAR('Журнал операций'!$B$25:$B$224+0)=$F$3)*(MONTH('Журнал операций'!$B$25:$B$224+0)=9)*(COUNTIF(Справочник!$C$3:$C$10,'Журнал операций'!$E$25:$E$224)=0)*'Журнал операций'!$F$25:$F$224) | L20: =SUMPRODUCT(('Журнал операций'!$D$25:$D$224="Расход")*(YEAR('Журнал операций'!$B$25:$B$224+0)=$F$3)*(MONTH('Журнал операций'!$B$25:$B$224+0)=9)*(COUNTIF(Справочник!$C$3:$C$10,'Журнал операций'!$E$25:$E$224)=0)*'Журнал операций'!$F$25:$F$224)
J21: =TEXT(DATE($F$3,10,1),"mmm yy") | K21: =SUMPRODUCT(('Журнал операций'!$D$25:$D$224="Доход")*(YEAR('Журнал операций'!$B$25:$B$224+0)=$F$3)*(MONTH('Журнал операций'!$B$25:$B$224+0)=10)*(COUNTIF(Справочник!$C$3:$C$10,'Журнал операций'!$E$25:$E$224)=0)*'Журнал операций'!$F$25:$F$224) | L21: =SUMPRODUCT(('Журнал операций'!$D$25:$D$224="Расход")*(YEAR('Журнал операций'!$B$25:$B$224+0)=$F$3)*(MONTH('Журнал операций'!$B$25:$B$224+0)=10)*(COUNTIF(Справочник!$C$3:$C$10,'Журнал операций'!$E$25:$E$224)=0)*'Журнал операций'!$F$25:$F$224)
J22: =TEXT(DATE($F$3,11,1),"mmm yy") | K22: =SUMPRODUCT(('Журнал операций'!$D$25:$D$224="Доход")*(YEAR('Журнал операций'!$B$25:$B$224+0)=$F$3)*(MONTH('Журнал операций'!$B$25:$B$224+0)=11)*(COUNTIF(Справочник!$C$3:$C$10,'Журнал операций'!$E$25:$E$224)=0)*'Журнал операций'!$F$25:$F$224) | L22: =SUMPRODUCT(('Журнал операций'!$D$25:$D$224="Расход")*(YEAR('Журнал операций'!$B$25:$B$224+0)=$F$3)*(MONTH('Журнал операций'!$B$25:$B$224+0)=11)*(COUNTIF(Справочник!$C$3:$C$10,'Журнал операций'!$E$25:$E$224)=0)*'Журнал операций'!$F$25:$F$224)
J23: =TEXT(DATE($F$3,12,1),"mmm yy") | K23: =SUMPRODUCT(('Журнал операций'!$D$25:$D$224="Доход")*(YEAR('Журнал операций'!$B$25:$B$224+0)=$F$3)*(MONTH('Журнал операций'!$B$25:$B$224+0)=12)*(COUNTIF(Справочник!$C$3:$C$10,'Журнал операций'!$E$25:$E$224)=0)*'Журнал операций'!$F$25:$F$224) | L23: =SUMPRODUCT(('Журнал операций'!$D$25:$D$224="Расход")*(YEAR('Журнал операций'!$B$25:$B$224+0)=$F$3)*(MONTH('Журнал операций'!$B$25:$B$224+0)=12)*(COUNTIF(Справочник!$C$3:$C$10,'Журнал операций'!$E$25:$E$224)=0)*'Журнал операций'!$F$25:$F$224)

Sheet Журнал операций
A1: 📒 ЖУРНАЛ ОПЕРАЦИЙ
B3: Месяц: | C3: =Бюджет!$C$3 | E3: Год: | F3: =Бюджет!$F$3 | G3: ← изменить можно на вкладке «Бюджет»
B5: ДОХОД (месяц) | D5: РАСХОД (месяц) | F5: БАЛАНС (месяц)
B6: =SUMPRODUCT(($D$25:$D$224="Доход")*(YEAR($B$25:$B$224+0)=Бюджет!$F$3)*(MONTH($B$25:$B$224+0)=MATCH(Бюджет!$C$3,Справочник!$L$3:$L$14,0))*(COUNTIF(Справочник!$C$3:$C$10,$E$25:$E$224)=0)*$F$25:$F$224) | D6: =SUMPRODUCT(($D$25:$D$224="Расход")*(YEAR($B$25:$B$224+0)=Бюджет!$F$3)*(MONTH($B$25:$B$224+0)=MATCH(Бюджет!$C$3,Справочник!$L$3:$L$14,0))*(COUNTIF(Справочник!$C$3:$C$10,$E$25:$E$224)=0)*$F$25:$F$224) | F6: =B6-D6
B10: ОСТАТОК ПО СЧЕТАМ
B11: Счёт | C11: Остаток
B12: =IFERROR(IF(Справочник!$K$3="","",Справочник!$K$3),"") | C12: =IF(B12="","",SUMIFS($F$25:$F$224,$C$25:$C$224,B12,$D$25:$D$224,"Доход")-SUMIFS($F$25:$F$224,$C$25:$C$224,B12,$D$25:$D$224,"Расход"))
B13: =IFERROR(IF(Справочник!$K$4="","",Справочник!$K$4),"") | C13: =IF(B13="","",SUMIFS($F$25:$F$224,$C$25:$C$224,B13,$D$25:$D$224,"Доход")-SUMIFS($F$25:$F$224,$C$25:$C$224,B13,$D$25:$D$224,"Расход"))
B14: =IFERROR(IF(Справочник!$K$5="","",Справочник!$K$5),"") | C14: =IF(B14="","",SUMIFS($F$25:$F$224,$C$25:$C$224,B14,$D$25:$D$224,"Доход")-SUMIFS($F$25:$F$224,$C$25:$C$224,B14,$D$25:$D$224,"Расход"))
B15: =IFERROR(IF(Справочник!$K$6="","",Справочник!$K$6),"") | C15: =IF(B15="","",SUMIFS($F$25:$F$224,$C$25:$C$224,B15,$D$25:$D$224,"Доход")-SUMIFS($F$25:$F$224,$C$25:$C$224,B15,$D$25:$D$224,"Расход"))
B16: =IFERROR(IF(Справочник!$K$7="","",Справочник!$K$7),"") | C16: =IF(B16="","",SUMIFS($F$25:$F$224,$C$25:$C$224,B16,$D$25:$D$224,"Доход")-SUMIFS($F$25:$F$224,$C$25:$C$224,B16,$D$25:$D$224,"Расход"))
B17: =IFERROR(IF(Справочник!$K$8="","",Справочник!$K$8),"") | C17: =IF(B17="","",SUMIFS($F$25:$F$224,$C$25:$C$224,B17,$D$25:$D$224,"Доход")-SUMIFS($F$25:$F$224,$C$25:$C$224,B17,$D$25:$D$224,"Расход"))
B18: =IFERROR(IF(Справочник!$K$9="","",Справочник!$K$9),"") | C18: =IF(B18="","",SUMIFS($F$25:$F$224,$C$25:$C$224,B18,$D$25:$D$224,"Доход")-SUMIFS($F$25:$F$224,$C$25:$C$224,B18,$D$25:$D$224,"Расход"))
B19: =IFERROR(IF(Справочник!$K$10="","",Справочник!$K$10),"") | C19: =IF(B19="","",SUMIFS($F$25:$F$224,$C$25:$C$224,B19,$D$25:$D$224,"Доход")-SUMIFS($F$25:$F$224,$C$25:$C$224,B19,$D$25:$D$224,"Расход"))
B20: =IFERROR(IF(Справочник!$K$11="","",Справочник!$K$11),"") | C20: =IF(B20="","",SUMIFS($F$25:$F$224,$C$25:$C$224,B20,$D$25:$D$224,"Доход")-SUMIFS($F$25:$F$224,$C$25:$C$224,B20,$D$25:$D$224,"Расход"))
B21: =IFERROR(IF(Справочник!$K$12="","",Справочник!$K$12),"") | C21: =IF(B21="","",SUMIFS($F$25:$F$224,$C$25:$C$224,B21,$D$25:$D$224,"Доход")-SUMIFS($F$25:$F$224,$C$25:$C$224,B21,$D$25:$D$224,"Расход"))
B23: ✏️ ВНОСИТЕ ДОХОДЫ И РАСХОДЫ СЮДА
B24: Дата | C24: Счёт | D24: Тип | E24: Категория | F24: Сумма | G24: Описание | H24: Остаток
B25: 46027 | C25: Карта Сбербанк | D25: Доход | E25: Зарплата | F25: 75000 | H25: =IF(C25="","",SUMPRODUCT(($C$25:C25=C25)*(2*($D$25:D25="Доход")-1)*$F$25:F25))
B26: 46028 | C26: Карта Сбербанк | D26: Расход | E26: Аренда | F26: 28000 | H26: =IF(C26="","",SUMPRODUCT(($C$25:C26=C26)*(2*($D$25:D26="Доход")-1)*$F$25:F26))
B27: 46030 | C27: Наличные | D27: Расход | E27: Продукты | F27: 7500 | H27: =IF(C27="","",SUMPRODUCT(($C$25:C27=C27)*(2*($D$25:D27="Доход")-1)*$F$25:F27))
B28: 46032 | C28: Карта Сбербанк | D28: Расход | E28: Пополнение вклада | F28: 15000 | G28: перевод на вклад | H28: =IF(C28="","",SUMPRODUCT(($C$25:C28=C28)*(2*($D$25:D28="Доход")-1)*$F$25:F28))
B29: 46032 | C29: Вклад | D29: Доход | E29: Пополнение вклада | F29: 15000 | H29: =IF(C29="","",SUMPRODUCT(($C$25:C29=C29)*(2*($D$25:D29="Доход")-1)*$F$25:F29))
B30: 46037 | C30: Карта Тинькофф | D30: Доход | E30: Заказы | F30: 20000 | G30: у друга | H30: =IF(C30="","",SUMPRODUCT(($C$25:C30=C30)*(2*($D$25:D30="Доход")-1)*$F$25:F30))
B31: 46040 | C31: Карта Сбербанк | D31: Расход | E31: Кредит | F31: 9000 | H31: =IF(C31="","",SUMPRODUCT(($C$25:C31=C31)*(2*($D$25:D31="Доход")-1)*$F$25:F31))
B32: 46042 | C32: Наличные | D32: Доход | E32: Взял в долг | F32: 10000 | H32: =IF(C32="","",SUMPRODUCT(($C$25:C32=C32)*(2*($D$25:D32="Доход")-1)*$F$25:F32))
B33: 46047 | C33: Карта Сбербанк | D33: Расход | E33: Обучение | F33: 10000 | H33: =IF(C33="","",SUMPRODUCT(($C$25:C33=C33)*(2*($D$25:D33="Доход")-1)*$F$25:F33))
B34: 46055 | C34: Карта Сбербанк | D34: Доход | E34: Зарплата | F34: 75000 | H34: =IF(C34="","",SUMPRODUCT(($C$25:C34=C34)*(2*($D$25:D34="Доход")-1)*$F$25:F34))
B35: 46056 | C35: Карта Сбербанк | D35: Расход | E35: Аренда | F35: 28000 | H35: =IF(C35="","",SUMPRODUCT(($C$25:C35=C35)*(2*($D$25:D35="Доход")-1)*$F$25:F35))
B36: 46058 | C36: Наличные | D36: Расход | E36: Продукты | F36: 8000 | H36: =IF(C36="","",SUMPRODUCT(($C$25:C36=C36)*(2*($D$25:D36="Доход")-1)*$F$25:F36))
B37: 46061 | C37: Карта Сбербанк | D37: Расход | E37: Пополнение вклада | F37: 20000 | H37: =IF(C37="","",SUMPRODUCT(($C$25:C37=C37)*(2*($D$25:D37="Доход")-1)*$F$25:F37))
B38: 46061 | C38: Вклад | D38: Доход | E38: Пополнение вклада | F38: 20000 | H38: =IF(C38="","",SUMPRODUCT(($C$25:C38=C38)*(2*($D$25:D38="Доход")-1)*$F$25:F38))
B39: 46065 | C39: Карта Тинькофф | D39: Доход | E39: Заказы | F39: 30000 | H39: =IF(C39="","",SUMPRODUCT(($C$25:C39=C39)*(2*($D$25:D39="Доход")-1)*$F$25:F39))
B40: 46068 | C40: Наличные | D40: Расход | E40: Вернул долг | F40: 5000 | H40: =IF(C40="","",SUMPRODUCT(($C$25:C40=C40)*(2*($D$25:D40="Доход")-1)*$F$25:F40))
B41: 46071 | C41: Карта Сбербанк | D41: Расход | E41: Ипотека | F41: 18000 | H41: =IF(C41="","",SUMPRODUCT(($C$25:C41=C41)*(2*($D$25:D41="Доход")-1)*$F$25:F41))
H42: =IF(C42="","",SUMPRODUCT(($C$25:C42=C42)*(2*($D$25:D42="Доход")-1)*$F$25:F42))
H43: =IF(C43="","",SUMPRODUCT(($C$25:C43=C43)*(2*($D$25:D43="Доход")-1)*$F$25:F43))
H44: =IF(C44="","",SUMPRODUCT(($C$25:C44=C44)*(2*($D$25:D44="Доход")-1)*$F$25:F44))
H45: =IF(C45="","",SUMPRODUCT(($C$25:C45=C45)*(2*($D$25:D45="Доход")-1)*$F$25:F45))
H46: =IF(C46="","",SUMPRODUCT(($C$25:C46=C46)*(2*($D$25:D46="Доход")-1)*$F$25:F46))
...

Sheet Трекер привычек
A1: 🌿 ТРЕКЕР ПРИВЫЧЕК
A2: Месяц: | B2: Июль | C2: Год: | D2: 2026
B4: =UPPER(TEXT(DATE($D$2,MATCH($B$2,Справочник!$L$3:$L$14,0),1),"mmmm"))&CHAR(10)&TEXT(DATE($D$2,MATCH($B$2,Справочник!$L$3:$L$14,0),1),"d mmmm yyyy") | C4: НЕДЕЛЯ 1 | J4: НЕДЕЛЯ 2 | Q4: НЕДЕЛЯ 3 | X4: НЕДЕЛЯ 4 | AE4: ДОП.
C5: =TEXT(DATE($D$2,MATCH($B$2,Справочник!$L$3:$L$14,0),1)+0,"ddd") | D5: =TEXT(DATE($D$2,MATCH($B$2,Справочник!$L$3:$L$14,0),1)+1,"ddd") | E5: =TEXT(DATE($D$2,MATCH($B$2,Справочник!$L$3:$L$14,0),1)+2,"ddd") | F5: =TEXT(DATE($D$2,MATCH($B$2,Справочник!$L$3:$L$14,0),1)+3,"ddd") | G5: =TEXT(DATE($D$2,MATCH($B$2,Справочник!$L$3:$L$14,0),1)+4,"ddd") | H5: =TEXT(DATE($D$2,MATCH($B$2,Справочник!$L$3:$L$14,0),1)+5,"ddd") | I5: =TEXT(DATE($D$2,MATCH($B$2,Справочник!$L$3:$L$14,0),1)+6,"ddd") | J5: =TEXT(DATE($D$2,MATCH($B$2,Справочник!$L$3:$L$14,0),1)+7,"ddd") | K5: =TEXT(DATE($D$2,MATCH($B$2,Справочник!$L$3:$L$14,0),1)+8,"ddd") | L5: =TEXT(DATE($D$2,MATCH($B$2,Справочник!$L$3:$L$14,0),1)+9,"ddd") | M5: =TEXT(DATE($D$2,MATCH($B$2,Справочник!$L$3:$L$14,0),1)+10,"ddd") | N5: =TEXT(DATE($D$2,MATCH($B$2,Справочник!$L$3:$L$14,0),1)+11,"ddd") | O5: =TEXT(DATE($D$2,MATCH($B$2,Справочник!$L$3:$L$14,0),1)+12,"ddd") | P5: =TEXT(DATE($D$2,MATCH($B$2,Справочник!$L$3:$L$14,0),1)+13,"ddd") | Q5: =TEXT(DATE($D$2,MATCH($B$2,Справочник!$L$3:$L$14,0),1)+14,"ddd") | R5: =TEXT(DATE($D$2,MATCH($B$2,Справочник!$L$3:$L$14,0),1)+15,"ddd") | S5: =TEXT(DATE($D$2,MATCH($B$2,Справочник!$L$3:$L$14,0),1)+16,"ddd") | T5: =TEXT(DATE($D$2,MATCH($B$2,Справочник!$L$3:$L$14,0),1)+17,"ddd") | U5: =TEXT(DATE($D$2,MATCH($B$2,Справочник!$L$3:$L$14,0),1)+18,"ddd") | V5: =TEXT(DATE($D$2,MATCH($B$2,Справочник!$L$3:$L$14,0),1)+19,"ddd") | W5: =TEXT(DATE($D$2,MATCH($B$2,Справочник!$L$3:$L$14,0),1)+20,"ddd") | X5: =TEXT(DATE($D$2,MATCH($B$2,Справочник!$L$3:$L$14,0),1)+21,"ddd") | Y5: =TEXT(DATE($D$2,MATCH($B$2,Справочник!$L$3:$L$14,0),1)+22,"ddd") | Z5: =TEXT(DATE($D$2,MATCH($B$2,Справочник!$L$3:$L$14,0),1)+23,"ddd") | AA5: =TEXT(DATE($D$2,MATCH($B$2,Справочник!$L$3:$L$14,0),1)+24,"ddd") | AB5: =TEXT(DATE($D$2,MATCH($B$2,Справочник!$L$3:$L$14,0),1)+25,"ddd") | AC5: =TEXT(DATE($D$2,MATCH($B$2,Справочник!$L$3:$L$14,0),1)+26,"ddd") | AD5: =TEXT(DATE($D$2,MATCH($B$2,Справочник!$L$3:$L$14,0),1)+27,"ddd") | AE5: =TEXT(DATE($D$2,MATCH($B$2,Справочник!$L$3:$L$14,0),1)+28,"ddd") | AF5: =TEXT(DATE($D$2,MATCH($B$2,Справочник!$L$3:$L$14,0),1)+29,"ddd") | AG5: =TEXT(DATE($D$2,MATCH($B$2,Справочник!$L$3:$L$14,0),1)+30,"ddd")
C6: =DAY(DATE($D$2,MATCH($B$2,Справочник!$L$3:$L$14,0),1)+0) | D6: =DAY(DATE($D$2,MATCH($B$2,Справочник!$L$3:$L$14,0),1)+1) | E6: =DAY(DATE($D$2,MATCH($B$2,Справочник!$L$3:$L$14,0),1)+2) | F6: =DAY(DATE($D$2,MATCH($B$2,Справочник!$L$3:$L$14,0),1)+3) | G6: =DAY(DATE($D$2,MATCH($B$2,Справочник!$L$3:$L$14,0),1)+4) | H6: =DAY(DATE($D$2,MATCH($B$2,Справочник!$L$3:$L$14,0),1)+5) | I6: =DAY(DATE($D$2,MATCH($B$2,Справочник!$L$3:$L$14,0),1)+6) | J6: =DAY(DATE($D$2,MATCH($B$2,Справочник!$L$3:$L$14,0),1)+7) | K6: =DAY(DATE($D$2,MATCH($B$2,Справочник!$L$3:$L$14,0),1)+8) | L6: =DAY(DATE($D$2,MATCH($B$2,Справочник!$L$3:$L$14,0),1)+9) | M6: =DAY(DATE($D$2,MATCH($B$2,Справочник!$L$3:$L$14,0),1)+10) | N6: =DAY(DATE($D$2,MATCH($B$2,Справочник!$L$3:$L$14,0),1)+11) | O6: =DAY(DATE($D$2,MATCH($B$2,Справочник!$L$3:$L$14,0),1)+12) | P6: =DAY(DATE($D$2,MATCH($B$2,Справочник!$L$3:$L$14,0),1)+13) | Q6: =DAY(DATE($D$2,MATCH($B$2,Справочник!$L$3:$L$14,0),1)+14) | R6: =DAY(DATE($D$2,MATCH($B$2,Справочник!$L$3:$L$14,0),1)+15) | S6: =DAY(DATE($D$2,MATCH($B$2,Справочник!$L$3:$L$14,0),1)+16) | T6: =DAY(DATE($D$2,MATCH($B$2,Справочник!$L$3:$L$14,0),1)+17) | U6: =DAY(DATE($D$2,MATCH($B$2,Справочник!$L$3:$L$14,0),1)+18) | V6: =DAY(DATE($D$2,MATCH($B$2,Справочник!$L$3:$L$14,0),1)+19) | W6: =DAY(DATE($D$2,MATCH($B$2,Справочник!$L$3:$L$14,0),1)+20) | X6: =DAY(DATE($D$2,MATCH($B$2,Справочник!$L$3:$L$14,0),1)+21) | Y6: =DAY(DATE($D$2,MATCH($B$2,Справочник!$L$3:$L$14,0),1)+22) | Z6: =DAY(DATE($D$2,MATCH($B$2,Справочник!$L$3:$L$14,0),1)+23) | AA6: =DAY(DATE($D$2,MATCH($B$2,Справочник!$L$3:$L$14,0),1)+24) | AB6: =DAY(DATE($D$2,MATCH($B$2,Справочник!$L$3:$L$14,0),1)+25) | AC6: =DAY(DATE($D$2,MATCH($B$2,Справочник!$L$3:$L$14,0),1)+26) | AD6: =DAY(DATE($D$2,MATCH($B$2,Справочник!$L$3:$L$14,0),1)+27) | AE6: =DAY(DATE($D$2,MATCH($B$2,Справочник!$L$3:$L$14,0),1)+28) | AF6: =DAY(DATE($D$2,MATCH($B$2,Справочник!$L$3:$L$14,0),1)+29) | AG6: =DAY(DATE($D$2,MATCH($B$2,Справочник!$L$3:$L$14,0),1)+30)
A7: 1 | B7: 💧 2 литра воды | C7: FALSE | D7: FALSE | E7: FALSE | F7: FALSE | G7: FALSE | H7: FALSE | I7: FALSE | J7: FALSE | K7: FALSE | L7: FALSE | M7: FALSE | N7: FALSE | O7: FALSE | P7: FALSE | Q7: FALSE | R7: FALSE | S7: FALSE | T7: FALSE | U7: FALSE | V7: FALSE | W7: FALSE | X7: FALSE | Y7: FALSE | Z7: FALSE | AA7: FALSE | AB7: FALSE | AC7: FALSE | AD7: FALSE | AE7: FALSE | AF7: FALSE | AG7: FALSE
A8: 2 | B8: 🏃 Спортзал в 19:00 | C8: FALSE | D8: FALSE | E8: FALSE | F8: FALSE | G8: FALSE | H8: FALSE | I8: FALSE | J8: FALSE | K8: FALSE | L8: FALSE | M8: FALSE | N8: FALSE | O8: FALSE | P8: FALSE | Q8: FALSE | R8: FALSE | S8: FALSE | T8: FALSE | U8: FALSE | V8: FALSE | W8: FALSE | X8: FALSE | Y8: FALSE | Z8: FALSE | AA8: FALSE | AB8: FALSE | AC8: FALSE | AD8: FALSE | AE8: FALSE | AF8: FALSE | AG8: FALSE
A9: 3 | B9: 📖 Чтение 30 мин | C9: FALSE | D9: FALSE | E9: FALSE | F9: FALSE | G9: FALSE | H9: FALSE | I9: FALSE | J9: FALSE | K9: FALSE | L9: FALSE | M9: FALSE | N9: FALSE | O9: FALSE | P9: FALSE | Q9: FALSE | R9: FALSE | S9: FALSE | T9: FALSE | U9: FALSE | V9: FALSE | W9: FALSE | X9: FALSE | Y9: FALSE | Z9: FALSE | AA9: FALSE | AB9: FALSE | AC9: FALSE | AD9: FALSE | AE9: FALSE | AF9: FALSE | AG9: FALSE
A10: 4 | B10: 📓 Ведение дневника | C10: FALSE | D10: FALSE | E10: FALSE | F10: FALSE | G10: FALSE | H10: FALSE | I10: FALSE | J10: FALSE | K10: FALSE | L10: FALSE | M10: FALSE | N10: FALSE | O10: FALSE | P10: FALSE | Q10: FALSE | R10: FALSE | S10: FALSE | T10: FALSE | U10: FALSE | V10: FALSE | W10: FALSE | X10: FALSE | Y10: FALSE | Z10: FALSE | AA10: FALSE | AB10: FALSE | AC10: FALSE | AD10: FALSE | AE10: FALSE | AF10: FALSE | AG10: FALSE
A11: 5 | B11: 💼 Работа — 5 часов | C11: FALSE | D11: FALSE | E11: FALSE | F11: FALSE | G11: FALSE | H11: FALSE | I11: FALSE | J11: FALSE | K11: FALSE | L11: FALSE | M11: FALSE | N11: FALSE | O11: FALSE | P11: FALSE | Q11: FALSE | R11: FALSE | S11: FALSE | T11: FALSE | U11: FALSE | V11: FALSE | W11: FALSE | X11: FALSE | Y11: FALSE | Z11: FALSE | AA11: FALSE | AB11: FALSE | AC11: FALSE | AD11: FALSE | AE11: FALSE | AF11: FALSE | AG11: FALSE
A12: 6 | B12: 💪 Подработка — 2 часа | C12: FALSE | D12: FALSE | E12: FALSE | F12: FALSE | G12: FALSE | H12: FALSE | I12: FALSE | J12: FALSE | K12: FALSE | L12: FALSE | M12: FALSE | N12: FALSE | O12: FALSE | P12: FALSE | Q12: FALSE | R12: FALSE | S12: FALSE | T12: FALSE | U12: FALSE | V12: FALSE | W12: FALSE | X12: FALSE | Y12: FALSE | Z12: FALSE | AA12: FALSE | AB12: FALSE | AC12: FALSE | AD12: FALSE | AE12: FALSE | AF12: FALSE | AG12: FALSE
A13: 7 | B13: 🧘 Растяжка 15 мин | C13: FALSE | D13: FALSE | E13: FALSE | F13: FALSE | G13: FALSE | H13: FALSE | I13: FALSE | J13: FALSE | K13: FALSE | L13: FALSE | M13: FALSE | N13: FALSE | O13: FALSE | P13: FALSE | Q13: FALSE | R13: FALSE | S13: FALSE | T13: FALSE | U13: FALSE | V13: FALSE | W13: FALSE | X13: FALSE | Y13: FALSE | Z13: FALSE | AA13: FALSE | AB13: FALSE | AC13: FALSE | AD13: FALSE | AE13: FALSE | AF13: FALSE | AG13: FALSE
A14: 8 | B14: 🙏 Практика благодарности | C14: FALSE | D14: FALSE | E14: FALSE | F14: FALSE | G14: FALSE | H14: FALSE | I14: FALSE | J14: FALSE | K14: FALSE | L14: FALSE | M14: FALSE | N14: FALSE | O14: FALSE | P14: FALSE | Q14: FALSE | R14: FALSE | S14: FALSE | T14: FALSE | U14: FALSE | V14: FALSE | W14: FALSE | X14: FALSE | Y14: FALSE | Z14: FALSE | AA14: FALSE | AB14: FALSE | AC14: FALSE | AD14: FALSE | AE14: FALSE | AF14: FALSE | AG14: FALSE
A15: 9 | C15: FALSE | D15: FALSE | E15: FALSE | F15: FALSE | G15: FALSE | H15: FALSE | I15: FALSE | J15: FALSE | K15: FALSE | L15: FALSE | M15: FALSE | N15: FALSE | O15: FALSE | P15: FALSE | Q15: FALSE | R15: FALSE | S15: FALSE | T15: FALSE | U15: FALSE | V15: FALSE | W15: FALSE | X15: FALSE | Y15: FALSE | Z15: FALSE | AA15: FALSE | AB15: FALSE | AC15: FALSE | AD15: FALSE | AE15: FALSE | AF15: FALSE | AG15: FALSE
A16: 10 | C16: FALSE | D16: FALSE | E16: FALSE | F16: FALSE | G16: FALSE | H16: FALSE | I16: FALSE | J16: FALSE | K16: FALSE | L16: FALSE | M16: FALSE | N16: FALSE | O16: FALSE | P16: FALSE | Q16: FALSE | R16: FALSE | S16: FALSE | T16: FALSE | U16: FALSE | V16: FALSE | W16: FALSE | X16: FALSE | Y16: FALSE | Z16: FALSE | AA16: FALSE | AB16: FALSE | AC16: FALSE | AD16: FALSE | AE16: FALSE | AF16: FALSE | AG16: FALSE
A17: 11 | C17: FALSE | D17: FALSE | E17: FALSE | F17: FALSE | G17: FALSE | H17: FALSE | I17: FALSE | J17: FALSE | K17: FALSE | L17: FALSE | M17: FALSE | N17: FALSE | O17: FALSE | P17: FALSE | Q17: FALSE | R17: FALSE | S17: FALSE | T17: FALSE | U17: FALSE | V17: FALSE | W17: FALSE | X17: FALSE | Y17: FALSE | Z17: FALSE | AA17: FALSE | AB17: FALSE | AC17: FALSE | AD17: FALSE | AE17: FALSE | AF17: FALSE | AG17: FALSE
A18: 12 | C18: FALSE | D18: FALSE | E18: FALSE | F18: FALSE | G18: FALSE | H18: FALSE | I18: FALSE | J18: FALSE | K18: FALSE | L18: FALSE | M18: FALSE | N18: FALSE | O18: FALSE | P18: FALSE | Q18: FALSE | R18: FALSE | S18: FALSE | T18: FALSE | U18: FALSE | V18: FALSE | W18: FALSE | X18: FALSE | Y18: FALSE | Z18: FALSE | AA18: FALSE | AB18: FALSE | AC18: FALSE | AD18: FALSE | AE18: FALSE | AF18: FALSE | AG18: FALSE
A19: 13 | C19: FALSE | D19: FALSE | E19: FALSE | F19: FALSE | G19: FALSE | H19: FALSE | I19: FALSE | J19: FALSE | K19: FALSE | L19: FALSE | M19: FALSE | N19: FALSE | O19: FALSE | P19: FALSE | Q19: FALSE | R19: FALSE | S19: FALSE | T19: FALSE | U19: FALSE | V19: FALSE | W19: FALSE | X19: FALSE | Y19: FALSE | Z19: FALSE | AA19: FALSE | AB19: FALSE | AC19: FALSE | AD19: FALSE | AE19: FALSE | AF19: FALSE | AG19: FALSE
A20: 14 | C20: FALSE | D20: FALSE | E20: FALSE | F20: FALSE | G20: FALSE | H20: FALSE | I20: FALSE | J20: FALSE | K20: FALSE | L20: FALSE | M20: FALSE | N20: FALSE | O20: FALSE | P20: FALSE | Q20: FALSE | R20: FALSE | S20: FALSE | T20: FALSE | U20: FALSE | V20: FALSE | W20: FALSE | X20: FALSE | Y20: FALSE | Z20: FALSE | AA20: FALSE | AB20: FALSE | AC20: FALSE | AD20: FALSE | AE20: FALSE | AF20: FALSE | AG20: FALSE
A21: 15 | C21: FALSE | D21: FALSE | E21: FALSE | F21: FALSE | G21: FALSE | H21: FALSE | I21: FALSE | J21: FALSE | K21: FALSE | L21: FALSE | M21: FALSE | N21: FALSE | O21: FALSE | P21: FALSE | Q21: FALSE | R21: FALSE | S21: FALSE | T21: FALSE | U21: FALSE | V21: FALSE | W21: FALSE | X21: FALSE | Y21: FALSE | Z21: FALSE | AA21: FALSE | AB21: FALSE | AC21: FALSE | AD21: FALSE | AE21: FALSE | AF21: FALSE | AG21: FALSE
A22: 16 | C22: FALSE | D22: FALSE | E22: FALSE | F22: FALSE | G22: FALSE | H22: FALSE | I22: FALSE | J22: FALSE | K22: FALSE | L22: FALSE | M22: FALSE | N22: FALSE | O22: FALSE | P22: FALSE | Q22: FALSE | R22: FALSE | S22: FALSE | T22: FALSE | U22: FALSE | V22: FALSE | W22: FALSE | X22: FALSE | Y22: FALSE | Z22: FALSE | AA22: FALSE | AB22: FALSE | AC22: FALSE | AD22: FALSE | AE22: FALSE | AF22: FALSE | AG22: FALSE
A23: 17 | C23: FALSE | D23: FALSE | E23: FALSE | F23: FALSE | G23: FALSE | H23: FALSE | I23: FALSE | J23: FALSE | K23: FALSE | L23: FALSE | M23: FALSE | N23: FALSE | O23: FALSE | P23: FALSE | Q23: FALSE | R23: FALSE | S23: FALSE | T23: FALSE | U23: FALSE | V23: FALSE | W23: FALSE | X23: FALSE | Y23: FALSE | Z23: FALSE | AA23: FALSE | AB23: FALSE | AC23: FALSE | AD23: FALSE | AE23: FALSE | AF23: FALSE | AG23: FALSE
A24: 18 | C24: FALSE | D24: FALSE | E24: FALSE | F24: FALSE | G24: FALSE | H24: FALSE | I24: FALSE | J24: FALSE | K24: FALSE | L24: FALSE | M24: FALSE | N24: FALSE | O24: FALSE | P24: FALSE | Q24: FALSE | R24: FALSE | S24: FALSE | T24: FALSE | U24: FALSE | V24: FALSE | W24: FALSE | X24: FALSE | Y24: FALSE | Z24: FALSE | AA24: FALSE | AB24: FALSE | AC24: FALSE | AD24: FALSE | AE24: FALSE | AF24: FALSE | AG24: FALSE
A25: 19 | C25: FALSE | D25: FALSE | E25: FALSE | F25: FALSE | G25: FALSE | H25: FALSE | I25: FALSE | J25: FALSE | K25: FALSE | L25: FALSE | M25: FALSE | N25: FALSE | O25: FALSE | P25: FALSE | Q25: FALSE | R25: FALSE | S25: FALSE | T25: FALSE | U25: FALSE | V25: FALSE | W25: FALSE | X25: FALSE | Y25: FALSE | Z25: FALSE | AA25: FALSE | AB25: FALSE | AC25: FALSE | AD25: FALSE | AE25: FALSE | AF25: FALSE | AG25: FALSE
A26: 20 | C26: FALSE | D26: FALSE | E26: FALSE | F26: FALSE | G26: FALSE | H26: FALSE | I26: FALSE | J26: FALSE | K26: FALSE | L26: FALSE | M26: FALSE | N26: FALSE | O26: FALSE | P26: FALSE | Q26: FALSE | R26: FALSE | S26: FALSE | T26: FALSE | U26: FALSE | V26: FALSE | W26: FALSE | X26: FALSE | Y26: FALSE | Z26: FALSE | AA26: FALSE | AB26: FALSE | AC26: FALSE | AD26: FALSE | AE26: FALSE | AF26: FALSE | AG26: FALSE
... A30: 24 | C30: FALSE | D30: FALSE | E30: FALSE | F30: FALSE | G30: FALSE | H30: FALSE | I30: FALSE | J30: FALSE | K30: FALSE | L30: FALSE | M30: FALSE | N30: FALSE | O30: FALSE | P30: FALSE | Q30: FALSE | R30: FALSE | S30: FALSE | T30: FALSE | U30: FALSE | V30: FALSE | W30: FALSE | X30: FALSE | Y30: FALSE | Z30: FALSE | AA30: FALSE | AB30: FALSE | AC30: FALSE | AD30: FALSE | AE30: FALSE | AF30: FALSE | AG30: FALSE
B31: ВЫПОЛНЕНЫ | C31: =COUNTIFS($B$7:$B$30,"<>",C7:C30,TRUE) | D31: =COUNTIFS($B$7:$B$30,"<>",D7:D30,TRUE) | E31: =COUNTIFS($B$7:$B$30,"<>",E7:E30,TRUE) | F31: =COUNTIFS($B$7:$B$30,"<>",F7:F30,TRUE) | G31: =COUNTIFS($B$7:$B$30,"<>",G7:G30,TRUE) | H31: =COUNTIFS($B$7:$B$30,"<>",H7:H30,TRUE) | I31: =COUNTIFS($B$7:$B$30,"<>",I7:I30,TRUE) | J31: =COUNTIFS($B$7:$B$30,"<>",J7:J30,TRUE) | ... AG31: =COUNTIFS($B$7:$B$30,"<>",AG7:AG30,TRUE)
B32: НЕВЫПОЛНЕНЫ | C32: =COUNTIFS($B$7:$B$30,"<>",C7:C30,FALSE) | D32: =COUNTIFS($B$7:$B$30,"<>",D7:D30,FALSE) | E32: =COUNTIFS($B$7:$B$30,"<>",E7:E30,FALSE) | F32: =COUNTIFS($B$7:$B$30,"<>",F7:F30,FALSE) | G32: =COUNTIFS($B$7:$B$30,"<>",G7:G30,FALSE) | H32: =COUNTIFS($B$7:$B$30,"<>",H7:H30,FALSE) | I32: =COUNTIFS($B$7:$B$30,"<>",I7:I30,FALSE) | J32: =COUNTIFS($B$7:$B$30,"<>",J7:J30,FALSE) | ... AG32: =COUNTIFS($B$7:$B$30,"<>",AG7:AG30,FALSE)
B33: ПРОГРЕСС % | C33: =IFERROR(C31/(C31+C32),0) | D33: =IFERROR(D31/(D31+D32),0) | E33: =IFERROR(E31/(E31+E32),0) | F33: =IFERROR(F31/(F31+F32),0) | G33: =IFERROR(G31/(G31+G32),0) | H33: =IFERROR(H31/(H31+H32),0) | I33: =IFERROR(I31/(I31+I32),0) | J33: =IFERROR(J31/(J31+J32),0) | ... AG33: =IFERROR(AG31/(AG31+AG32),0)
B35: ЕЖЕНЕДЕЛЬНЫЕ ПРИВЫЧКИ | C35: НЕДЕЛЯ 1 | D35: НЕДЕЛЯ 2 | E35: НЕДЕЛЯ 3 | F35: НЕДЕЛЯ 4 | G35: НЕДЕЛЯ 5
B36: 🏋 Спортзал 3 раза в неделю | C36: FALSE | D36: FALSE | E36: FALSE | F36: FALSE | G36: FALSE
B37: 💰 Анализ расходов | C37: FALSE | D37: FALSE | E37: FALSE | F37: FALSE | G37: FALSE
C38: FALSE | D38: FALSE | E38: FALSE | F38: FALSE | G38: FALSE
C39: FALSE | D39: FALSE | E39: FALSE | F39: FALSE | G39: FALSE
C40: FALSE | D40: FALSE | E40: FALSE | F40: FALSE | G40: FALSE
C41: FALSE | D41: FALSE | E41: FALSE | F41: FALSE | G41: FALSE
C42: FALSE | D42: FALSE | E42: FALSE | F42: FALSE | G42: FALSE
C43: FALSE | D43: FALSE | E43: FALSE | F43: FALSE | G43: FALSE
C44: FALSE | D44: FALSE | E44: FALSE | F44: FALSE | G44: FALSE
C45: FALSE | D45: FALSE | E45: FALSE | F45: FALSE | G45: FALSE
...

Sheet Планировщик задач
A1: 🗂 МОИ ЗАДАЧИ
I2: Месяц: | J2: Июль | K2: Год: | L2: 2026
B3: Задача | C3: Срок | D3: Дни ⏳ | E3: Приоритет | F3: ✅ | G3: Категория
B4: 🚶 10k шагов | C4: =TODAY()+(-3) | D4: =C4-TODAY() | E4: Высокий | F4: FALSE | G4: Личное
B5: 📕 20 страниц книги | C5: =TODAY()+(-1) | D5: =C5-TODAY() | E5: Срочно | F5: FALSE | G5: Личное
B6: ✉️ Отправить письмо клиенту | C6: =TODAY()+(0) | D6: =C6-TODAY() | E6: Средний | F6: TRUE | G6: Работа
B7: 🧘 Медитация (10 мин) | C7: =TODAY()+(0) | D7: =C7-TODAY() | E7: Высокий | F7: FALSE | G7: Личное
B8: 💰 Посчитать бюджет на месяц | C8: =TODAY()+(2) | D8: =C8-TODAY() | E8: Низкий | F8: FALSE | G8: Другое
B9: 🎬 Сделать рилс | C9: =TODAY()+(3) | D9: =C9-TODAY() | E9: Срочно | F9: FALSE | G9: Работа
B10: 💳 Оплатить кредит | C10: =TODAY()+(-2) | D10: =C10-TODAY() | E10: Срочно | F10: TRUE | G10: Другое
B11: 🗓 План на следующую неделю | C11: =TODAY()+(1) | D11: =C11-TODAY() | E11: Средний | F11: FALSE | G11: Работа
B12: 📞 Позвонить маме | C12: =TODAY()+(0) | D12: =C12-TODAY() | E12: Средний | F12: TRUE | G12: Личное
B13: 🎤 Подготовить речь для конфы | C13: =TODAY()+(2) | D13: =C13-TODAY() | E13: Высокий | F13: FALSE | G13: Личное
B14: 📊 Бюджет на месяц (план) | C14: =TODAY()+(10) | D14: =C14-TODAY() | E14: Низкий | F14: FALSE | G14: Личное
B15: 📈 Составить отчёт | C15: =TODAY()+(-4) | D15: =C15-TODAY() | E15: Высокий | F15: FALSE | G15: Работа
F16: FALSE
F17: FALSE
F18: FALSE
F19: FALSE
F20: FALSE
F21: FALSE
F22: FALSE
F23: FALSE
B25: СРОЧНЫЕ | C25: =SUMPRODUCT(($E$4:$E$23="Срочно")*(YEAR($C$4:$C$23+0)=$L$2)*(MONTH($C$4:$C$23+0)=MATCH($J$2,Справочник!$L$3:$L$14,0))) | E25: ВСЕГО ЗАДАЧ | G25: =SUMPRODUCT((YEAR($C$4:$C$23+0)=$L$2)*(MONTH($C$4:$C$23+0)=MATCH($J$2,Справочник!$L$3:$L$14,0))) | I25: Срочно | J25: =SUMPRODUCT(($E$4:$E$23="Срочно")*(YEAR($C$4:$C$23+0)=$L$2)*(MONTH($C$4:$C$23+0)=MATCH($J$2,Справочник!$L$3:$L$14,0))) | L25: ЗАДАЧ ВЫПОЛНЕНО (месяц) | M25: =SUMPRODUCT(($F$4:$F$23=TRUE)*(YEAR($C$4:$C$23+0)=$L$2)*(MONTH($C$4:$C$23+0)=MATCH($J$2,Справочник!$L$3:$L$14,0)))&"/"&SUMPRODUCT((YEAR($C$4:$C$23+0)=$L$2)*(MONTH($C$4:$C$23+0)=MATCH($J$2,Справочник!$L$3:$L$14,0))) | N25: Работа | O25: =SUMPRODUCT(($G$4:$G$23="Работа")*(YEAR($C$4:$C$23+0)=$L$2)*(MONTH($C$4:$C$23+0)=MATCH($J$2,Справочник!$L$3:$L$14,0)))
B26: ВЫСОКИЙ ПРИОРИТЕТ | C26: =SUMPRODUCT(($E$4:$E$23="Высокий")*(YEAR($C$4:$C$23+0)=$L$2)*(MONTH($C$4:$C$23+0)=MATCH($J$2,Справочник!$L$3:$L$14,0))) | E26: ЛИЧНЫЕ | G26: =SUMPRODUCT(($G$4:$G$23="Личное")*(YEAR($C$4:$C$23+0)=$L$2)*(MONTH($C$4:$C$23+0)=MATCH($J$2,Справочник!$L$3:$L$14,0))) | I26: Высокий | J26: =SUMPRODUCT(($E$4:$E$23="Высокий")*(YEAR($C$4:$C$23+0)=$L$2)*(MONTH($C$4:$C$23+0)=MATCH($J$2,Справочник!$L$3:$L$14,0))) | L26: ПРОГРЕСС (месяц) | M26: =IFERROR(SUMPRODUCT(($F$4:$F$23=TRUE)*(YEAR($C$4:$C$23+0)=$L$2)*(MONTH($C$4:$C$23+0)=MATCH($J$2,Справочник!$L$3:$L$14,0)))/SUMPRODUCT((YEAR($C$4:$C$23+0)=$L$2)*(MONTH($C$4:$C$23+0)=MATCH($J$2,Справочник!$L$3:$L$14,0))),0) | N26: Личное | O26: =SUMPRODUCT(($G$4:$G$23="Личное")*(YEAR($C$4:$C$23+0)=$L$2)*(MONTH($C$4:$C$23+0)=MATCH($J$2,Справочник!$L$3:$L$14,0)))
B27: СРЕДНИЙ ПРИОРИТЕТ | C27: =SUMPRODUCT(($E$4:$E$23="Средний")*(YEAR($C$4:$C$23+0)=$L$2)*(MONTH($C$4:$C$23+0)=MATCH($J$2,Справочник!$L$3:$L$14,0))) | E27: РАБОТА | G27: =SUMPRODUCT(($G$4:$G$23="Работа")*(YEAR($C$4:$C$23+0)=$L$2)*(MONTH($C$4:$C$23+0)=MATCH($J$2,Справочник!$L$3:$L$14,0))) | I27: Средний | J27: =SUMPRODUCT(($E$4:$E$23="Средний")*(YEAR($C$4:$C$23+0)=$L$2)*(MONTH($C$4:$C$23+0)=MATCH($J$2,Справочник!$L$3:$L$14,0))) | L27: ДЕДЛАЙН СЕГОДНЯ | M27: =COUNTIF($C$4:$C$23,TODAY()) | N27: Другое | O27: =SUMPRODUCT(($G$4:$G$23="Другое")*(YEAR($C$4:$C$23+0)=$L$2)*(MONTH($C$4:$C$23+0)=MATCH($J$2,Справочник!$L$3:$L$14,0)))
B28: НИЗКИЙ ПРИОРИТЕТ | C28: =SUMPRODUCT(($E$4:$E$23="Низкий")*(YEAR($C$4:$C$23+0)=$L$2)*(MONTH($C$4:$C$23+0)=MATCH($J$2,Справочник!$L$3:$L$14,0))) | E28: ДРУГИЕ | G28: =SUMPRODUCT(($G$4:$G$23="Другое")*(YEAR($C$4:$C$23+0)=$L$2)*(MONTH($C$4:$C$23+0)=MATCH($J$2,Справочник!$L$3:$L$14,0))) | I28: Низкий | J28: =SUMPRODUCT(($E$4:$E$23="Низкий")*(YEAR($C$4:$C$23+0)=$L$2)*(MONTH($C$4:$C$23+0)=MATCH($J$2,Справочник!$L$3:$L$14,0))) | L28: ПРОСРОЧЕННЫЕ ЗАДАЧИ | M28: =COUNTIFS($C$4:$C$23,"<"&TODAY(),$F$4:$F$23,FALSE)
B30: Выделение задач: | C30: (Все)
B47: СРОЧНЫЕ | G47: ВЫСОКИЙ ПРИОРИТЕТ
B48: Задача | C48: Срок | D48: Дни | E48: Тип | G48: Задача | H48: Срок | I48: Дни | J48: Тип
B49: =IFERROR(FILTER($B$4:$B$23,($E$4:$E$23="Срочно")*(YEAR($C$4:$C$23+0)=$L$2)*(MONTH($C$4:$C$23+0)=MATCH($J$2,Справочник!$L$3:$L$14,0))),"") | C49: =IFERROR(FILTER($C$4:$C$23,($E$4:$E$23="Срочно")*(YEAR($C$4:$C$23+0)=$L$2)*(MONTH($C$4:$C$23+0)=MATCH($J$2,Справочник!$L$3:$L$14,0))),"") | D49: =IFERROR(FILTER($D$4:$D$23,($E$4:$E$23="Срочно")*(YEAR($C$4:$C$23+0)=$L$2)*(MONTH($C$4:$C$23+0)=MATCH($J$2,Справочник!$L$3:$L$14,0))),"") | E49: =IFERROR(FILTER($G$4:$G$23,($E$4:$E$23="Срочно")*(YEAR($C$4:$C$23+0)=$L$2)*(MONTH($C$4:$C$23+0)=MATCH($J$2,Справочник!$L$3:$L$14,0))),"") | G49: =IFERROR(FILTER($B$4:$B$23,($E$4:$E$23="Высокий")*(YEAR($C$4:$C$23+0)=$L$2)*(MONTH($C$4:$C$23+0)=MATCH($J$2,Справочник!$L$3:$L$14,0))),"") | H49: =IFERROR(FILTER($C$4:$C$23,($E$4:$E$23="Высокий")*(YEAR($C$4:$C$23+0)=$L$2)*(MONTH($C$4:$C$23+0)=MATCH($J$2,Справочник!$L$3:$L$14,0))),"") | I49: =IFERROR(FILTER($D$4:$D$23,($E$4:$E$23="Высокий")*(YEAR($C$4:$C$23+0)=$L$2)*(MONTH($C$4:$C$23+0)=MATCH($J$2,Справочник!$L$3:$L$14,0))),"") | J49: =IFERROR(FILTER($G$4:$G$23,($E$4:$E$23="Высокий")*(YEAR($C$4:$C$23+0)=$L$2)*(MONTH($C$4:$C$23+0)=MATCH($J$2,Справочник!$L$3:$L$14,0))),"")
B55: СРЕДНИЙ ПРИОРИТЕТ | G55: НИЗКИЙ ПРИОРИТЕТ
B56: Задача | C56: Срок | D56: Дни | E56: Тип | G56: Задача | H56: Срок | I56: Дни | J56: Тип
B57: =IFERROR(FILTER($B$4:$B$23,($E$4:$E$23="Средний")*(YEAR($C$4:$C$23+0)=$L$2)*(MONTH($C$4:$C$23+0)=MATCH($J$2,Справочник!$L$3:$L$14,0))),"") | C57: =IFERROR(FILTER($C$4:$C$23,($E$4:$E$23="Средний")*(YEAR($C$4:$C$23+0)=$L$2)*(MONTH($C$4:$C$23+0)=MATCH($J$2,Справочник!$L$3:$L$14,0))),"") | D57: =IFERROR(FILTER($D$4:$D$23,($E$4:$E$23="Средний")*(YEAR($C$4:$C$23+0)=$L$2)*(MONTH($C$4:$C$23+0)=MATCH($J$2,Справочник!$L$3:$L$14,0))),"") | E57: =IFERROR(FILTER($G$4:$G$23,($E$4:$E$23="Средний")*(YEAR($C$4:$C$23+0)=$L$2)*(MONTH($C$4:$C$23+0)=MATCH($J$2,Справочник!$L$3:$L$14,0))),"") | G57: =IFERROR(FILTER($B$4:$B$23,($E$4:$E$23="Низкий")*(YEAR($C$4:$C$23+0)=$L$2)*(MONTH($C$4:$C$23+0)=MATCH($J$2,Справочник!$L$3:$L$14,0))),"") | H57: =IFERROR(FILTER($C$4:$C$23,($E$4:$E$23="Низкий")*(YEAR($C$4:$C$23+0)=$L$2)*(MONTH($C$4:$C$23+0)=MATCH($J$2,Справочник!$L$3:$L$14,0))),"") | I57: =IFERROR(FILTER($D$4:$D$23,($E$4:$E$23="Низкий")*(YEAR($C$4:$C$23+0)=$L$2)*(MONTH($C$4:$C$23+0)=MATCH($J$2,Справочник!$L$3:$L$14,0))),"") | J57: =IFERROR(FILTER($G$4:$G$23,($E$4:$E$23="Низкий")*(YEAR($C$4:$C$23+0)=$L$2)*(MONTH($C$4:$C$23+0)=MATCH($J$2,Справочник!$L$3:$L$14,0))),"")

Sheet Справочник
A1: СПРАВОЧНИК КАТЕГОРИЙ И СПИСКОВ
A2: Категории доходов | B2: Категории расходов | C2: Служебные (переводы/долг/инвест.) | D2: Категории задач | E2: Приоритет | F2: Статус задачи | J2: Все категории (для выпадающего списка) | K2: Счета / способы оплаты | L2: Месяцы | M2: Годы
A3: Зарплата | B3: Аренда | C3: Взял в долг | D3: Работа | E3: Срочно | F3: Не начато | J3: Зарплата | K3: Наличные | L3: Январь | M3: 2023
A4: Заказы | B4: Продукты | C4: Вернул долг | D4: Личное | E4: Высокий | F4: В процессе | J4: Заказы | K4: Карта Сбербанк | L4: Февраль | M4: 2024
A5: Подарок | B5: Обучение | C5: Дал в долг | D5: Другое | E5: Средний | F5: Готово | J5: Подарок | K5: Карта Тинькофф | L5: Март | M5: 2025
B6: Кредит | C6: Вернули долг | E6: Низкий | J6: Аренда | K6: Вклад | L6: Апрель | M6: 2026
B7: Субподряд | C7: Пополнение вклада | J7: Продукты | K7: Кредит 1 | L7: Май | M7: 2027
B8: Ипотека | C8: Снятие со вклада | J8: Обучение | K8: Кредит 2 | L8: Июнь | M8: 2028
B9: Подарок | C9: Инвестиции: пополнение | J9: Кредит | K9: Инвестиционный счёт | L9: Июль | M9: 2029
B10: Аутсорс | C10: Инвестиции: вывод | J10: Субподряд | L10: Август | M10: 2030
J11: Ипотека | K11: ✏ Добавьте сюда свои карты, наличные, вклады, кредиты или инвестсчета — они появятся в выпадающем списке «Счёт» в Бюджете. | L11: Сентябрь | M11: 2031
C12: ⚠ Эти категории — служебные (переводы между своими счетами, долги, инвестиции). Они не считаются доходом/расходом в сводке за месяц, но участвуют в остатках по счетам. Не изменяйте и не удаляйте их, если хотите корректный учёт. | J12: Аутсорс | L12: Октябрь | M12: 2032
J13: Взял в долг | L13: Ноябрь
J14: Вернул долг | L14: Декабрь
J15: Дал в долг
J16: Вернули долг
J17: Пополнение вклада
J18: Снятие со вклада
J19: Инвестиции: пополнение
J20: Инвестиции: вывод
